<?xml version="1.0"?>
<robot name="my_robot">
    <material name="green">
        <color rgba="0 0.6 0 1" />
    </material>
    <material name="gray">
        <color rgba="0.5 0.5 0.5 1"/>
    </material>

    <link name="base_footprint"/>
  
    <link name="base_link">
        <visual>
            <geometry>
                <box size="5 3.5 1.0"></box>
            </geometry>
            <material name="green"/>
            <origin xyz="0 0 0.5" rpy="0 0 0" />
        </visual>
    </link>


    <link name="right_wheel_r_link">
        <visual>
            <geometry>
                <cylinder radius="0.8" length="0.3" />
            </geometry>
            <origin xyz="0 0 0" rpy="1.57 0 0"/>  rotat wheel 180 degree about X axis
            <material name="gray"/>
        </visual>
    </link>

    <link name="right_wheel_f_link">
        <visual>
            <geometry>
                <cylinder radius="0.8" length="0.3"/>
            </geometry>
            <origin xyz="0 0 0" rpy="1.57 0 0"/>
            <material name="gray"/>
        </visual>
    </link>

    <link name="left_wheel_r_link">
        <visual>
            <geometry>
                <cylinder radius="0.8" length="0.3"/>
            </geometry>
            <origin xyz="0 0 0" rpy="1.57 0 0"/>
            <material name="gray"/>
        </visual>
    </link>

    <link name="left_wheel_f_link">
        <visual>
            <geometry>
                <cylinder radius="0.8" length="0.3"/>
            </geometry>
            <origin xyz="0 0 0" rpy="1.57 0 0"/>
            <material name="gray"/>
        </visual>
    </link>

    <joint name="base_joint" type="fixed">
        <parent link="base_footprint"/>
        <child link="base_link"/>
        <origin xyz="0 0 0.5" rpy="0 0 0"/>
    </joint>




    <joint name="base_right_wheel_r_joint" type="continuous">
        <parent link="base_link"/>
        <child link ="right_wheel_r_link"/>
        <origin xyz="-1.8 -1.9 0.3" rpy="0 0 0"/> ///distance between center and wheel 
        <axis xyz="0 1 0"/>
    </joint>

    <joint name="base_right_wheel_f_joint" type="continuous">
        <parent link="base_link"/>
        <child link="right_wheel_f_link"/>
        <origin xyz="1.8 -1.9 0.3" rpy="0 0 0"/>
        <axis xyz="0 1 0"/>
    </joint>

    <joint name="base_left_wheel_r_joint" type="continuous">
        <parent link="base_link"/>
        <child link="left_wheel_r_link"/>
        <origin xyz="-1.8 1.9 0.3" rpy="0 0 0"/>
        <axis xyz="0 1 0"/>
    </joint>

    <joint name="base_left_wheel_f_joint" type="continuous">
        <parent link="base_link"/>
        <child link="left_wheel_f_link"/>
        <origin xyz="1.8 1.9 0.3" rpy="0 0 0"/>
        <axis xyz="0 1 0"/>
    </joint>
    

</robot>


 